Workbook

Sheet 価格表
A1: 板金・塗装 価格表
A2: 店舗名 | C2: 改定日 | E2: 消費税率 | F2: 0.1
A3: ■ 使い方：黄色のセル（普通車 / 2tトラック / 4tトラック の列）に税抜の金額を入力してください。数式は入っていないので上書きして構いません。
A4: ■ グレーの「−」は該当なしの想定です。取り扱う場合は上書きして金額を入力できます。8行目は記入例です（不要なら行ごと削除してください）。
A5: ■ 表示は税抜の目安です。損傷の程度・車両の状態・部品代により変動します。部品代・材料費は別途実費。「見積書」シートでこの表から単価を呼び出せます。
A6: No. | B6: 区分 | C6: 作業内容 | D6: 単位 | E6: 単価（税抜・円） | H6: 作業日数目安 | I6: 備考
E7: 普通車 | F7: 2tトラック | G7: 4tトラック
A8: 例 | B8: 板金（キズ・凹み） | C8: （記入例）バンパーの擦りキズ修理 | D8: 1箇所 | E8: 22000 | F8: 26000 | G8: 30000 | H8: 1日 | I8: この行は記入例です
A9: 1 | B9: 板金（キズ・凹み） | C9: 小キズ・擦りキズ修理（10cm程度） | D9: 1箇所 | H9: 1日 | I9: 塗装込み
A10: 2 | B10: 板金（キズ・凹み） | C10: 凹み修理（直径10cm程度） | D10: 1箇所 | H10: 1〜2日
A11: 3 | B11: 板金（キズ・凹み） | C11: 凹み修理（直径20cm程度） | D11: 1箇所 | H11: 2〜3日
A12: 4 | B12: 板金（キズ・凹み） | C12: 大きな凹み（パネルの1/2程度） | D12: 1パネル | H12: 3〜5日
A13: 5 | B13: 板金（キズ・凹み） | C13: 折れ・深い損傷の板金（引き出し含む） | D13: 1パネル | H13: 4〜7日
A14: 6 | B14: 板金（キズ・凹み） | C14: デントリペア（塗装なし・浅い凹み） | D14: 1箇所 | H14: 半日 | I14: 塗装が割れていない場合
A15: 7 | B15: 板金（キズ・凹み） | C15: サビ・腐食部の切開＋板金 | D15: 1箇所 | H15: 3〜5日 | I15: 範囲により変動
A16: 8 | B16: 板金（キズ・凹み） | C16: パネル交換（工賃のみ） | D16: 1パネル | H16: 3〜5日 | I16: 部品代は別途実費
A17: 9 | B17: 塗装 | C17: 部分塗装（30cm四方程度） | D17: 1箇所 | H17: 1〜2日
A18: 10 | B18: 塗装 | C18: 1パネル塗装（ソリッド・単色） | D18: 1パネル | H18: 2〜3日
A19: 11 | B19: 塗装 | C19: 1パネル塗装（メタリック） | D19: 1パネル | H19: 2〜3日
A20: 12 | B20: 塗装 | C20: 1パネル塗装（パール・3コート） | D20: 1パネル | H20: 3〜4日
A21: 13 | B21: 塗装 | C21: ぼかし塗装（隣接パネル） | D21: 1パネル | H21: 1日 | I21: 色差を抑える場合
A22: 14 | B22: 塗装 | C22: クリア再塗装（塗装剥がれ・色あせ） | D22: 1パネル | H22: 2〜3日
A23: 15 | B23: 塗装 | C23: 下地処理・サフェーサー | D23: 1パネル | H23: 1日
A24: 16 | B24: 塗装 | C24: 錆止め・防錆塗装 | D24: 1箇所 | H24: 1日
A25: 17 | B25: パネル別（板金＋塗装） | C25: フロントバンパー | D25: 1本 | H25: 2〜4日 | I25: 脱着込み
A26: 18 | B26: パネル別（板金＋塗装） | C26: リヤバンパー | D26: 1本 | H26: 2〜4日 | I26: 脱着込み
A27: 19 | B27: パネル別（板金＋塗装） | C27: ボンネット | D27: 1枚 | H27: 3〜4日
A28: 20 | B28: パネル別（板金＋塗装） | C28: フロントフェンダー（片側） | D28: 1枚 | H28: 3〜4日
A29: 21 | B29: パネル別（板金＋塗装） | C29: フロントドア（片側） | D29: 1枚 | H29: 3〜4日
A30: 22 | B30: パネル別（板金＋塗装） | C30: リヤドア（片側） | D30: 1枚 | F30: − | G30: − | H30: 3〜4日 | I30: トラックはダブルキャブのみ別途
A31: 23 | B31: パネル別（板金＋塗装） | C31: リヤフェンダー／クォーターパネル | D31: 1枚 | F31: − | G31: − | H31: 4〜6日
A32: 24 | B32: パネル別（板金＋塗装） | C32: バックドア／トランクリッド | D32: 1枚 | F32: − | G32: − | H32: 3〜4日
A33: 25 | B33: パネル別（板金＋塗装） | C33: ルーフ（キャブルーフ） | D33: 1枚 | H33: 4〜6日
A34: 26 | B34: パネル別（板金＋塗装） | C34: サイドステップ／ロッカーパネル | D34: 1箇所 | H34: 3〜4日
A35: 27 | B35: パネル別（板金＋塗装） | C35: フロントパネル・グリルまわり | D35: 1箇所 | H35: 2〜3日
A36: 28 | B36: パネル別（板金＋塗装） | C36: ドアミラーカバー | D36: 1個 | H36: 1〜2日
A37: 29 | B37: トラック関連 | C37: あおり 板金・塗装 | D37: 1枚 | E37: − | H37: 2〜4日
A38: 30 | B38: トラック関連 | C38: あおり 交換（工賃のみ） | D38: 1枚 | E38: − | H38: 2〜3日 | I38: 部品代は別途実費
A39: 31 | B39: トラック関連 | C39: 荷台床板 修理・張替え | D39: 1式 | E39: − | H39: 3〜5日 | I39: 材料費別途
A40: 32 | B40: トラック関連 | C40: 荷台フレーム 防錆塗装 | D40: 1式 | E40: − | H40: 2〜4日
...

Sheet 見積書
A1: 板金・塗装 お見積り
A3: お客様名 | D3: 見積日
A4: 車種区分 | D4: 担当
A5: 車両（型式・年式） | D5: 消費税率 | E5: =価格表!$F$2 -> 0.1
A6: ※ B4の車種区分と各行の作業内容を選ぶと、価格表シートの単価を自動で読み込みます（黄色＝入力欄 / 白＝自動計算）。
A8: No. | B8: 作業内容 | C8: 単位 | D8: 数量 | E8: 単価（税抜） | F8: 金額（税抜） | G8: 備考
A9: 1 | C9: =IFERROR(INDEX(価格表!$D$9:$D$53,MATCH($B9,価格表!$C$9:$C$53,0)),"") | E9: =IF($B9="","",IFERROR(INDEX(価格表!$E$9:$G$53,MATCH($B9,価格表!$C$9:$C$53,0),MATCH($B$4,価格表!$E$7:$G$7,0)),"")) | F9: =IF(OR($B9="",$D9=""),"",IFERROR($D9*$E9,""))
A10: 2 | C10: =IFERROR(INDEX(価格表!$D$9:$D$53,MATCH($B10,価格表!$C$9:$C$53,0)),"") | E10: =IF($B10="","",IFERROR(INDEX(価格表!$E$9:$G$53,MATCH($B10,価格表!$C$9:$C$53,0),MATCH($B$4,価格表!$E$7:$G$7,0)),"")) | F10: =IF(OR($B10="",$D10=""),"",IFERROR($D10*$E10,""))
A11: 3 | C11: =IFERROR(INDEX(価格表!$D$9:$D$53,MATCH($B11,価格表!$C$9:$C$53,0)),"") | E11: =IF($B11="","",IFERROR(INDEX(価格表!$E$9:$G$53,MATCH($B11,価格表!$C$9:$C$53,0),MATCH($B$4,価格表!$E$7:$G$7,0)),"")) | F11: =IF(OR($B11="",$D11=""),"",IFERROR($D11*$E11,""))
A12: 4 | C12: =IFERROR(INDEX(価格表!$D$9:$D$53,MATCH($B12,価格表!$C$9:$C$53,0)),"") | E12: =IF($B12="","",IFERROR(INDEX(価格表!$E$9:$G$53,MATCH($B12,価格表!$C$9:$C$53,0),MATCH($B$4,価格表!$E$7:$G$7,0)),"")) | F12: =IF(OR($B12="",$D12=""),"",IFERROR($D12*$E12,""))
A13: 5 | C13: =IFERROR(INDEX(価格表!$D$9:$D$53,MATCH($B13,価格表!$C$9:$C$53,0)),"") | E13: =IF($B13="","",IFERROR(INDEX(価格表!$E$9:$G$53,MATCH($B13,価格表!$C$9:$C$53,0),MATCH($B$4,価格表!$E$7:$G$7,0)),"")) | F13: =IF(OR($B13="",$D13=""),"",IFERROR($D13*$E13,""))
A14: 6 | C14: =IFERROR(INDEX(価格表!$D$9:$D$53,MATCH($B14,価格表!$C$9:$C$53,0)),"") | E14: =IF($B14="","",IFERROR(INDEX(価格表!$E$9:$G$53,MATCH($B14,価格表!$C$9:$C$53,0),MATCH($B$4,価格表!$E$7:$G$7,0)),"")) | F14: =IF(OR($B14="",$D14=""),"",IFERROR($D14*$E14,""))
A15: 7 | C15: =IFERROR(INDEX(価格表!$D$9:$D$53,MATCH($B15,価格表!$C$9:$C$53,0)),"") | E15: =IF($B15="","",IFERROR(INDEX(価格表!$E$9:$G$53,MATCH($B15,価格表!$C$9:$C$53,0),MATCH($B$4,価格表!$E$7:$G$7,0)),"")) | F15: =IF(OR($B15="",$D15=""),"",IFERROR($D15*$E15,""))
A16: 8 | C16: =IFERROR(INDEX(価格表!$D$9:$D$53,MATCH($B16,価格表!$C$9:$C$53,0)),"") | E16: =IF($B16="","",IFERROR(INDEX(価格表!$E$9:$G$53,MATCH($B16,価格表!$C$9:$C$53,0),MATCH($B$4,価格表!$E$7:$G$7,0)),"")) | F16: =IF(OR($B16="",$D16=""),"",IFERROR($D16*$E16,""))
A17: 9 | C17: =IFERROR(INDEX(価格表!$D$9:$D$53,MATCH($B17,価格表!$C$9:$C$53,0)),"") | E17: =IF($B17="","",IFERROR(INDEX(価格表!$E$9:$G$53,MATCH($B17,価格表!$C$9:$C$53,0),MATCH($B$4,価格表!$E$7:$G$7,0)),"")) | F17: =IF(OR($B17="",$D17=""),"",IFERROR($D17*$E17,""))
A18: 10 | C18: =IFERROR(INDEX(価格表!$D$9:$D$53,MATCH($B18,価格表!$C$9:$C$53,0)),"") | E18: =IF($B18="","",IFERROR(INDEX(価格表!$E$9:$G$53,MATCH($B18,価格表!$C$9:$C$53,0),MATCH($B$4,価格表!$E$7:$G$7,0)),"")) | F18: =IF(OR($B18="",$D18=""),"",IFERROR($D18*$E18,""))
A19: 11 | C19: =IFERROR(INDEX(価格表!$D$9:$D$53,MATCH($B19,価格表!$C$9:$C$53,0)),"") | E19: =IF($B19="","",IFERROR(INDEX(価格表!$E$9:$G$53,MATCH($B19,価格表!$C$9:$C$53,0),MATCH($B$4,価格表!$E$7:$G$7,0)),"")) | F19: =IF(OR($B19="",$D19=""),"",IFERROR($D19*$E19,""))
A20: 12 | C20: =IFERROR(INDEX(価格表!$D$9:$D$53,MATCH($B20,価格表!$C$9:$C$53,0)),"") | E20: =IF($B20="","",IFERROR(INDEX(価格表!$E$9:$G$53,MATCH($B20,価格表!$C$9:$C$53,0),MATCH($B$4,価格表!$E$7:$G$7,0)),"")) | F20: =IF(OR($B20="",$D20=""),"",IFERROR($D20*$E20,""))
... A28: 20 | C28: =IFERROR(INDEX(価格表!$D$9:$D$53,MATCH($B28,価格表!$C$9:$C$53,0)),"") | E28: =IF($B28="","",IFERROR(INDEX(価格表!$E$9:$G$53,MATCH($B28,価格表!$C$9:$C$53,0),MATCH($B$4,価格表!$E$7:$G$7,0)),"")) | F28: =IF(OR($B28="",$D28=""),"",IFERROR($D28*$E28,""))
E30: 小計（税抜） | F30: =SUM(F9:F28) -> 0
E31: 消費税 | F31: =ROUND(F30*$E$5,0) -> 0
E32: 合計（税込） | F32: =F30+F31 -> 0
A34: ※ 部品代・材料費・代車費用は別途実費。単価が空欄の場合は価格表シートに金額を入力してください。
A35: ※ 見積り有効期限は発行日より30日間。実車確認により金額が変わる場合があります。
